Workbook

Sheet Presupuesto
A1: PRESUPUESTO DE IMPORTACIÓN (PROVISORIO)
A2: Cliente: | F2: Contenedor:
A3: CUIT: | F3: ETD / ETA:
A4: Detalle pedido: | F4: Carrier:
A5: Origen / Cond. Venta: | F5: Freetime:
A7: RESUMEN DE LA OPERACIÓN
B8: USD | C8: ARS
A9: ① Mercadería + costo financiero | B9: =E33+E34 -> 0 | C9: =B9*B$86 -> 0
A10: ② Tributos VEP (pago a AFIP) | B10: =B82 -> 10 | C10: =C82 -> 15100
A11: ③ Gastos operativos + IVA | B11: =D103+C123 -> 0 | C11: =E103+D123 -> 0
A12: TOTAL DESEMBOLSADO (c/IVA) | B12: =B126 -> 10 | C12: =C126 -> 15100
A13: Costo total s/IVA y percepciones | B13: =B127 -> 10 | C13: =C127 -> 15100
A14: Incidencia s/FOB | B14: =IF(E33>0,(B10+B11)/E33,0) -> 0
A16: DETALLE DE MERCADERÍA
A17: Descripción | B17: NCM | C17: FOB Unit. | D17: Cant | E17: FOB Total | F17: FOB Decl.U | G17: FOB Decl.T | H17: % Partic | I17: Peso/Vol
C18: 0 | D18: 0 | E18: =C18*D18 -> 0 | F18: 0 | G18: =F18*D18 -> 0 | H18: =IF(G$33>0,G18/G$33,0) -> 0 | I18: 0
C19: 0 | D19: 0 | E19: =C19*D19 -> 0 | F19: 0 | G19: =F19*D19 -> 0 | H19: =IF(G$33>0,G19/G$33,0) -> 0 | I19: 0
C20: 0 | D20: 0 | E20: =C20*D20 -> 0 | F20: 0 | G20: =F20*D20 -> 0 | H20: =IF(G$33>0,G20/G$33,0) -> 0 | I20: 0
C21: 0 | D21: 0 | E21: =C21*D21 -> 0 | F21: 0 | G21: =F21*D21 -> 0 | H21: =IF(G$33>0,G21/G$33,0) -> 0 | I21: 0
C22: 0 | D22: 0 | E22: =C22*D22 -> 0 | F22: 0 | G22: =F22*D22 -> 0 | H22: =IF(G$33>0,G22/G$33,0) -> 0 | I22: 0
C23: 0 | D23: 0 | E23: =C23*D23 -> 0 | F23: 0 | G23: =F23*D23 -> 0 | H23: =IF(G$33>0,G23/G$33,0) -> 0 | I23: 0
C24: 0 | D24: 0 | E24: =C24*D24 -> 0 | F24: 0 | G24: =F24*D24 -> 0 | H24: =IF(G$33>0,G24/G$33,0) -> 0 | I24: 0
C25: 0 | D25: 0 | E25: =C25*D25 -> 0 | F25: 0 | G25: =F25*D25 -> 0 | H25: =IF(G$33>0,G25/G$33,0) -> 0 | I25: 0
C26: 0 | D26: 0 | E26: =C26*D26 -> 0 | F26: 0 | G26: =F26*D26 -> 0 | H26: =IF(G$33>0,G26/G$33,0) -> 0 | I26: 0
C27: 0 | D27: 0 | E27: =C27*D27 -> 0 | F27: 0 | G27: =F27*D27 -> 0 | H27: =IF(G$33>0,G27/G$33,0) -> 0 | I27: 0
C28: 0 | D28: 0 | E28: =C28*D28 -> 0 | F28: 0 | G28: =F28*D28 -> 0 | H28: =IF(G$33>0,G28/G$33,0) -> 0 | I28: 0
C29: 0 | D29: 0 | E29: =C29*D29 -> 0 | F29: 0 | G29: =F29*D29 -> 0 | H29: =IF(G$33>0,G29/G$33,0) -> 0 | I29: 0
... C32: 0 | D32: 0 | E32: =C32*D32 -> 0 | F32: 0 | G32: =F32*D32 -> 0 | H32: =IF(G$33>0,G32/G$33,0) -> 0 | I32: 0
A33: TOTAL FOB | C33: FOB Pagado: | E33: =SUM(E18:E32) -> 0 | F33: FOB Declarado: | G33: =SUM(G18:G32) -> 0 | H33: Peso Total: | I33: =SUM(I18:I32) -> 0
A34: Costo financiero | C34: 0.025 | D34: Recargo: | E34: =E33*C34 -> 0 | F34: FOB + Finan: | G34: =E33+E34 -> 0
A36: VALOR DECLARADO EN ADUANA
A37: TC Tributos: | B37: 1510 | C37: Cotización del despacho
A38: FOB declarado | B38: =G33 -> 0 | C38: =B38*B$37 -> 0
A39: Flete declarado | B39: =D88/2 -> 0 | C39: =B39*B$37 -> 0
A40: Seguro declarado | B40: =E33*0.3% -> 0 | C40: =B40*B$37 -> 0
A41: CIF DECLARADO | B41: =SUM(B38:B40) -> 0 | C41: =B41*B$37 -> 0
A43: DERECHOS, TASAS Y ANTIDUMPING
A44: Producto | B44: CIF Producto | C44: %Der | D44: Derechos | E44: %Tasa | F44: Tasa Est. | G44: %Antid | H44: Antidump. | I44: Subtotal
A45: =A18 | B45: =G18+(B$39+B$40)*H18 -> 0 | C45: 0 | D45: =B45*C45 -> 0 | E45: 0.03 | F45: =B45*E45 -> 0 | G45: 0 | H45: =B45*G45 -> 0 | I45: =D45+F45+H45 -> 0
A46: =A19 | B46: =G19+(B$39+B$40)*H19 -> 0 | C46: 0 | D46: =B46*C46 -> 0 | E46: 0.03 | F46: =B46*E46 -> 0 | G46: 0 | H46: =B46*G46 -> 0 | I46: =D46+F46+H46 -> 0
...

Sheet Costeo
A1: COSTO POR PRODUCTO
A2: Producto | B2: Costo FOB | C2: Imp+Gas Prorr | D2: Costo c/IVA | E2: s/IVA y Perc. | F2: c/IVA ARS | G2: s/IVA y Perc. ARS | H2: Nota
A3: =Presupuesto!A18 | B3: =IF(Presupuesto!D18>0,Presupuesto!C18+Presupuesto!E34*(Presupuesto!E18/Presupuesto!E$33)/Presupuesto!D18,0) -> 0 | C3: =IF(Presupuesto!D18>0,(Presupuesto!I45+Presupuesto!K65+Presupuesto!B$81*(Presupuesto!E18/Presupuesto!E$33)+Presupuesto!C$104*(Presupuesto!E18/Presupuesto!E$33)+Presupuesto!E$104*(IF(Presupuesto!I$33>0,Presupuesto!I18/Presupuesto!I$33,Presupuesto!E18/Presupuesto!E$33))+Presupuesto!C123*(Presupuesto!E18/Presupuesto!E$33))/Presupuesto!D18,0) -> 0 | D3: =B3+C3 -> 0 | E3: =IF(Presupuesto!D18>0,D3-(Presupuesto!D65+Presupuesto!F65+Presupuesto!H65+Presupuesto!J65+Presupuesto!C123*(Presupuesto!E18/Presupuesto!E$33))/Presupuesto!D18,0) -> 0 | F3: =D3*Presupuesto!B$86 -> 0 | G3: =E3*Presupuesto!B$86 -> 0
A4: =Presupuesto!A19 | B4: =IF(Presupuesto!D19>0,Presupuesto!C19+Presupuesto!E34*(Presupuesto!E19/Presupuesto!E$33)/Presupuesto!D19,0) -> 0 | C4: =IF(Presupuesto!D19>0,(Presupuesto!I46+Presupuesto!K66+Presupuesto!B$81*(Presupuesto!E19/Presupuesto!E$33)+Presupuesto!C$104*(Presupuesto!E19/Presupuesto!E$33)+Presupuesto!E$104*(IF(Presupuesto!I$33>0,Presupuesto!I19/Presupuesto!I$33,Presupuesto!E19/Presupuesto!E$33))+Presupuesto!C123*(Presupuesto!E19/Presupuesto!E$33))/Presupuesto!D19,0) -> 0 | D4: =B4+C4 -> 0 | E4: =IF(Presupuesto!D19>0,D4-(Presupuesto!D66+Presupuesto!F66+Presupuesto!H66+Presupuesto!J66+Presupuesto!C123*(Presupuesto!E19/Presupuesto!E$33))/Presupuesto!D19,0) -> 0 | F4: =D4*Presupuesto!B$86 -> 0 | G4: =E4*Presupuesto!B$86 -> 0
A5: =Presupuesto!A20 | B5: =IF(Presupuesto!D20>0,Presupuesto!C20+Presupuesto!E34*(Presupuesto!E20/Presupuesto!E$33)/Presupuesto!D20,0) -> 0 | C5: =IF(Presupuesto!D20>0,(Presupuesto!I47+Presupuesto!K67+Presupuesto!B$81*(Presupuesto!E20/Presupuesto!E$33)+Presupuesto!C$104*(Presupuesto!E20/Presupuesto!E$33)+Presupuesto!E$104*(IF(Presupuesto!I$33>0,Presupuesto!I20/Presupuesto!I$33,Presupuesto!E20/Presupuesto!E$33))+Presupuesto!C123*(Presupuesto!E20/Presupuesto!E$33))/Presupuesto!D20,0) -> 0 | D5: =B5+C5 -> 0 | E5: =IF(Presupuesto!D20>0,D5-(Presupuesto!D67+Presupuesto!F67+Presupuesto!H67+Presupuesto!J67+Presupuesto!C123*(Presupuesto!E20/Presupuesto!E$33))/Presupuesto!D20,0) -> 0 | F5: =D5*Presupuesto!B$86 -> 0 | G5: =E5*Presupuesto!B$86 -> 0
A6: =Presupuesto!A21 | B6: =IF(Presupuesto!D21>0,Presupuesto!C21+Presupuesto!E34*(Presupuesto!E21/Presupuesto!E$33)/Presupuesto!D21,0) -> 0 | C6: =IF(Presupuesto!D21>0,(Presupuesto!I48+Presupuesto!K68+Presupuesto!B$81*(Presupuesto!E21/Presupuesto!E$33)+Presupuesto!C$104*(Presupuesto!E21/Presupuesto!E$33)+Presupuesto!E$104*(IF(Presupuesto!I$33>0,Presupuesto!I21/Presupuesto!I$33,Presupuesto!E21/Presupuesto!E$33))+Presupuesto!C123*(Presupuesto!E21/Presupuesto!E$33))/Presupuesto!D21,0) -> 0 | D6: =B6+C6 -> 0 | E6: =IF(Presupuesto!D21>0,D6-(Presupuesto!D68+Presupuesto!F68+Presupuesto!H68+Presupuesto!J68+Presupuesto!C123*(Presupuesto!E21/Presupuesto!E$33))/Presupuesto!D21,0) -> 0 | F6: =D6*Presupuesto!B$86 -> 0 | G6: =E6*Presupuesto!B$86 -> 0
A7: =Presupuesto!A22 | B7: =IF(Presupuesto!D22>0,Presupuesto!C22+Presupuesto!E34*(Presupuesto!E22/Presupuesto!E$33)/Presupuesto!D22,0) -> 0 | C7: =IF(Presupuesto!D22>0,(Presupuesto!I49+Presupuesto!K69+Presupuesto!B$81*(Presupuesto!E22/Presupuesto!E$33)+Presupuesto!C$104*(Presupuesto!E22/Presupuesto!E$33)+Presupuesto!E$104*(IF(Presupuesto!I$33>0,Presupuesto!I22/Presupuesto!I$33,Presupuesto!E22/Presupuesto!E$33))+Presupuesto!C123*(Presupuesto!E22/Presupuesto!E$33))/Presupuesto!D22,0) -> 0 | D7: =B7+C7 -> 0 | E7: =IF(Presupuesto!D22>0,D7-(Presupuesto!D69+Presupuesto!F69+Presupuesto!H69+Presupuesto!J69+Presupuesto!C123*(Presupuesto!E22/Presupuesto!E$33))/Presupuesto!D22,0) -> 0 | F7: =D7*Presupuesto!B$86 -> 0 | G7: =E7*Presupuesto!B$86 -> 0
A8: =Presupuesto!A23 | B8: =IF(Presupuesto!D23>0,Presupuesto!C23+Presupuesto!E34*(Presupuesto!E23/Presupuesto!E$33)/Presupuesto!D23,0) -> 0 | C8: =IF(Presupuesto!D23>0,(Presupuesto!I50+Presupuesto!K70+Presupuesto!B$81*(Presupuesto!E23/Presupuesto!E$33)+Presupuesto!C$104*(Presupuesto!E23/Presupuesto!E$33)+Presupuesto!E$104*(IF(Presupuesto!I$33>0,Presupuesto!I23/Presupuesto!I$33,Presupuesto!E23/Presupuesto!E$33))+Presupuesto!C123*(Presupuesto!E23/Presupuesto!E$33))/Presupuesto!D23,0) -> 0 | D8: =B8+C8 -> 0 | E8: =IF(Presupuesto!D23>0,D8-(Presupuesto!D70+Presupuesto!F70+Presupuesto!H70+Presupuesto!J70+Presupuesto!C123*(Presupuesto!E23/Presupuesto!E$33))/Presupuesto!D23,0) -> 0 | F8: =D8*Presupuesto!B$86 -> 0 | G8: =E8*Presupuesto!B$86 -> 0
A9: =Presupuesto!A24 | B9: =IF(Presupuesto!D24>0,Presupuesto!C24+Presupuesto!E34*(Presupuesto!E24/Presupuesto!E$33)/Presupuesto!D24,0) -> 0 | C9: =IF(Presupuesto!D24>0,(Presupuesto!I51+Presupuesto!K71+Presupuesto!B$81*(Presupuesto!E24/Presupuesto!E$33)+Presupuesto!C$104*(Presupuesto!E24/Presupuesto!E$33)+Presupuesto!E$104*(IF(Presupuesto!I$33>0,Presupuesto!I24/Presupuesto!I$33,Presupuesto!E24/Presupuesto!E$33))+Presupuesto!C123*(Presupuesto!E24/Presupuesto!E$33))/Presupuesto!D24,0) -> 0 | D9: =B9+C9 -> 0 | E9: =IF(Presupuesto!D24>0,D9-(Presupuesto!D71+Presupuesto!F71+Presupuesto!H71+Presupuesto!J71+Presupuesto!C123*(Presupuesto!E24/Presupuesto!E$33))/Presupuesto!D24,0) -> 0 | F9: =D9*Presupuesto!B$86 -> 0 | G9: =E9*Presupuesto!B$86 -> 0
A10: =Presupuesto!A25 | B10: =IF(Presupuesto!D25>0,Presupuesto!C25+Presupuesto!E34*(Presupuesto!E25/Presupuesto!E$33)/Presupuesto!D25,0) -> 0 | C10: =IF(Presupuesto!D25>0,(Presupuesto!I52+Presupuesto!K72+Presupuesto!B$81*(Presupuesto!E25/Presupuesto!E$33)+Presupuesto!C$104*(Presupuesto!E25/Presupuesto!E$33)+Presupuesto!E$104*(IF(Presupuesto!I$33>0,Presupuesto!I25/Presupuesto!I$33,Presupuesto!E25/Presupuesto!E$33))+Presupuesto!C123*(Presupuesto!E25/Presupuesto!E$33))/Presupuesto!D25,0) -> 0 | D10: =B10+C10 -> 0 | E10: =IF(Presupuesto!D25>0,D10-(Presupuesto!D72+Presupuesto!F72+Presupuesto!H72+Presupuesto!J72+Presupuesto!C123*(Presupuesto!E25/Presupuesto!E$33))/Presupuesto!D25,0) -> 0 | F10: =D10*Presupuesto!B$86 -> 0 | G10: =E10*Presupuesto!B$86 -> 0
A11: =Presupuesto!A26 | B11: =IF(Presupuesto!D26>0,Presupuesto!C26+Presupuesto!E34*(Presupuesto!E26/Presupuesto!E$33)/Presupuesto!D26,0) -> 0 | C11: =IF(Presupuesto!D26>0,(Presupuesto!I53+Presupuesto!K73+Presupuesto!B$81*(Presupuesto!E26/Presupuesto!E$33)+Presupuesto!C$104*(Presupuesto!E26/Presupuesto!E$33)+Presupuesto!E$104*(IF(Presupuesto!I$33>0,Presupuesto!I26/Presupuesto!I$33,Presupuesto!E26/Presupuesto!E$33))+Presupuesto!C123*(Presupuesto!E26/Presupuesto!E$33))/Presupuesto!D26,0) -> 0 | D11: =B11+C11 -> 0 | E11: =IF(Presupuesto!D26>0,D11-(Presupuesto!D73+Presupuesto!F73+Presupuesto!H73+Presupuesto!J73+Presupuesto!C123*(Presupuesto!E26/Presupuesto!E$33))/Presupuesto!D26,0) -> 0 | F11: =D11*Presupuesto!B$86 -> 0 | G11: =E11*Presupuesto!B$86 -> 0
A12: =Presupuesto!A27 | B12: =IF(Presupuesto!D27>0,Presupuesto!C27+Presupuesto!E34*(Presupuesto!E27/Presupuesto!E$33)/Presupuesto!D27,0) -> 0 | C12: =IF(Presupuesto!D27>0,(Presupuesto!I54+Presupuesto!K74+Presupuesto!B$81*(Presupuesto!E27/Presupuesto!E$33)+Presupuesto!C$104*(Presupuesto!E27/Presupuesto!E$33)+Presupuesto!E$104*(IF(Presupuesto!I$33>0,Presupuesto!I27/Presupuesto!I$33,Presupuesto!E27/Presupuesto!E$33))+Presupuesto!C123*(Presupuesto!E27/Presupuesto!E$33))/Presupuesto!D27,0) -> 0 | D12: =B12+C12 -> 0 | E12: =IF(Presupuesto!D27>0,D12-(Presupuesto!D74+Presupuesto!F74+Presupuesto!H74+Presupuesto!J74+Presupuesto!C123*(Presupuesto!E27/Presupuesto!E$33))/Presupuesto!D27,0) -> 0 | F12: =D12*Presupuesto!B$86 -> 0 | G12: =E12*Presupuesto!B$86 -> 0
A13: =Presupuesto!A28 | B13: =IF(Presupuesto!D28>0,Presupuesto!C28+Presupuesto!E34*(Presupuesto!E28/Presupuesto!E$33)/Presupuesto!D28,0) -> 0 | C13: =IF(Presupuesto!D28>0,(Presupuesto!I55+Presupuesto!K75+Presupuesto!B$81*(Presupuesto!E28/Presupuesto!E$33)+Presupuesto!C$104*(Presupuesto!E28/Presupuesto!E$33)+Presupuesto!E$104*(IF(Presupuesto!I$33>0,Presupuesto!I28/Presupuesto!I$33,Presupuesto!E28/Presupuesto!E$33))+Presupuesto!C123*(Presupuesto!E28/Presupuesto!E$33))/Presupuesto!D28,0) -> 0 | D13: =B13+C13 -> 0 | E13: =IF(Presupuesto!D28>0,D13-(Presupuesto!D75+Presupuesto!F75+Presupuesto!H75+Presupuesto!J75+Presupuesto!C123*(Presupuesto!E28/Presupuesto!E$33))/Presupuesto!D28,0) -> 0 | F13: =D13*Presupuesto!B$86 -> 0 | G13: =E13*Presupuesto!B$86 -> 0
A14: =Presupuesto!A29 | B14: =IF(Presupuesto!D29>0,Presupuesto!C29+Presupuesto!E34*(Presupuesto!E29/Presupuesto!E$33)/Presupuesto!D29,0) -> 0 | C14: =IF(Presupuesto!D29>0,(Presupuesto!I56+Presupuesto!K76+Presupuesto!B$81*(Presupuesto!E29/Presupuesto!E$33)+Presupuesto!C$104*(Presupuesto!E29/Presupuesto!E$33)+Presupuesto!E$104*(IF(Presupuesto!I$33>0,Presupuesto!I29/Presupuesto!I$33,Presupuesto!E29/Presupuesto!E$33))+Presupuesto!C123*(Presupuesto!E29/Presupuesto!E$33))/Presupuesto!D29,0) -> 0 | D14: =B14+C14 -> 0 | E14: =IF(Presupuesto!D29>0,D14-(Presupuesto!D76+Presupuesto!F76+Presupuesto!H76+Presupuesto!J76+Presupuesto!C123*(Presupuesto!E29/Presupuesto!E$33))/Presupuesto!D29,0) -> 0 | F14: =D14*Presupuesto!B$86 -> 0 | G14: =E14*Presupuesto!B$86 -> 0
A15: =Presupuesto!A30 | B15: =IF(Presupuesto!D30>0,Presupuesto!C30+Presupuesto!E34*(Presupuesto!E30/Presupuesto!E$33)/Presupuesto!D30,0) -> 0 | C15: =IF(Presupuesto!D30>0,(Presupuesto!I57+Presupuesto!K77+Presupuesto!B$81*(Presupuesto!E30/Presupuesto!E$33)+Presupuesto!C$104*(Presupuesto!E30/Presupuesto!E$33)+Presupuesto!E$104*(IF(Presupuesto!I$33>0,Presupuesto!I30/Presupuesto!I$33,Presupuesto!E30/Presupuesto!E$33))+Presupuesto!C123*(Presupuesto!E30/Presupuesto!E$33))/Presupuesto!D30,0) -> 0 | D15: =B15+C15 -> 0 | E15: =IF(Presupuesto!D30>0,D15-(Presupuesto!D77+Presupuesto!F77+Presupuesto!H77+Presupuesto!J77+Presupuesto!C123*(Presupuesto!E30/Presupuesto!E$33))/Presupuesto!D30,0) -> 0 | F15: =D15*Presupuesto!B$86 -> 0 | G15: =E15*Presupuesto!B$86 -> 0
A16: =Presupuesto!A31 | B16: =IF(Presupuesto!D31>0,Presupuesto!C31+Presupuesto!E34*(Presupuesto!E31/Presupuesto!E$33)/Presupuesto!D31,0) -> 0 | C16: =IF(Presupuesto!D31>0,(Presupuesto!I58+Presupuesto!K78+Presupuesto!B$81*(Presupuesto!E31/Presupuesto!E$33)+Presupuesto!C$104*(Presupuesto!E31/Presupuesto!E$33)+Presupuesto!E$104*(IF(Presupuesto!I$33>0,Presupuesto!I31/Presupuesto!I$33,Presupuesto!E31/Presupuesto!E$33))+Presupuesto!C123*(Presupuesto!E31/Presupuesto!E$33))/Presupuesto!D31,0) -> 0 | D16: =B16+C16 -> 0 | E16: =IF(Presupuesto!D31>0,D16-(Presupuesto!D78+Presupuesto!F78+Presupuesto!H78+Presupuesto!J78+Presupuesto!C123*(Presupuesto!E31/Presupuesto!E$33))/Presupuesto!D31,0) -> 0 | F16: =D16*Presupuesto!B$86 -> 0 | G16: =E16*Presupuesto!B$86 -> 0
A17: =Presupuesto!A32 | B17: =IF(Presupuesto!D32>0,Presupuesto!C32+Presupuesto!E34*(Presupuesto!E32/Presupuesto!E$33)/Presupuesto!D32,0) -> 0 | C17: =IF(Presupuesto!D32>0,(Presupuesto!I59+Presupuesto!K79+Presupuesto!B$81*(Presupuesto!E32/Presupuesto!E$33)+Presupuesto!C$104*(Presupuesto!E32/Presupuesto!E$33)+Presupuesto!E$104*(IF(Presupuesto!I$33>0,Presupuesto!I32/Presupuesto!I$33,Presupuesto!E32/Presupuesto!E$33))+Presupuesto!C123*(Presupuesto!E32/Presupuesto!E$33))/Presupuesto!D32,0) -> 0 | D17: =B17+C17 -> 0 | E17: =IF(Presupuesto!D32>0,D17-(Presupuesto!D79+Presupuesto!F79+Presupuesto!H79+Presupuesto!J79+Presupuesto!C123*(Presupuesto!E32/Presupuesto!E$33))/Presupuesto!D32,0) -> 0 | F17: =D17*Presupuesto!B$86 -> 0 | G17: =E17*Presupuesto!B$86 -> 0
A18: TOTAL | D18: =D3*Presupuesto!D18+D4*Presupuesto!D19+D5*Presupuesto!D20+D6*Presupuesto!D21+D7*Presupuesto!D22+D8*Presupuesto!D23+D9*Presupuesto!D24+D10*Presupuesto!D25+D11*Presupuesto!D26+D12*Presupuesto!D27+D13*Presupuesto!D28+D14*Presupuesto!D29+D15*Presupuesto!D30+D16*Presupuesto!D31+D17*Presupuesto!D32 -> 0
A19: CHECK (debe ser $0) | B19: =Presupuesto!B126-(D3*Presupuesto!D18+D4*Presupuesto!D19+D5*Presupuesto!D20+D6*Presupuesto!D21+D7*Presupuesto!D22+D8*Presupuesto!D23+D9*Presupuesto!D24+D10*Presupuesto!D25+D11*Presupuesto!D26+D12*Presupuesto!D27+D13*Presupuesto!D28+D14*Presupuesto!D29+D15*Presupuesto!D30+D16*Presupuesto!D31+D17*Presupuesto!D32) -> 10
A21: SIMULACIÓN DE VENTA (USD)
A22: Producto | B22: Costo c/IVA | C22: Margen % | D22: PV Sugerido | E22: PV Final | F22: PV Mercado | G22: Margen Real % | H22: Ganancia Unit
A23: =Presupuesto!A18 | B23: =D3 -> 0 | C23: 0.3 | D23: =B23*(1+C23) -> 0 | E23: 0 | F23: 0 | G23: =IF(AND(B23>0,E23>0),(E23-B23)/B23,0) -> 0 | H23: =IF(E23>0,E23-B23,0) -> 0
A24: =Presupuesto!A19 | B24: =D4 -> 0 | C24: 0.3 | D24: =B24*(1+C24) -> 0 | E24: 0 | F24: 0 | G24: =IF(AND(B24>0,E24>0),(E24-B24)/B24,0) -> 0 | H24: =IF(E24>0,E24-B24,0) -> 0
A25: =Presupuesto!A20 | B25: =D5 -> 0 | C25: 0.3 | D25: =B25*(1+C25) -> 0 | E25: 0 | F25: 0 | G25: =IF(AND(B25>0,E25>0),(E25-B25)/B25,0) -> 0 | H25: =IF(E25>0,E25-B25,0) -> 0
A26: =Presupuesto!A21 | B26: =D6 -> 0 | C26: 0.3 | D26: =B26*(1+C26) -> 0 | E26: 0 | F26: 0 | G26: =IF(AND(B26>0,E26>0),(E26-B26)/B26,0) -> 0 | H26: =IF(E26>0,E26-B26,0) -> 0
A27: =Presupuesto!A22 | B27: =D7 -> 0 | C27: 0.3 | D27: =B27*(1+C27) -> 0 | E27: 0 | F27: 0 | G27: =IF(AND(B27>0,E27>0),(E27-B27)/B27,0) -> 0 | H27: =IF(E27>0,E27-B27,0) -> 0
A28: =Presupuesto!A23 | B28: =D8 -> 0 | C28: 0.3 | D28: =B28*(1+C28) -> 0 | E28: 0 | F28: 0 | G28: =IF(AND(B28>0,E28>0),(E28-B28)/B28,0) -> 0 | H28: =IF(E28>0,E28-B28,0) -> 0
A29: =Presupuesto!A24 | B29: =D9 -> 0 | C29: 0.3 | D29: =B29*(1+C29) -> 0 | E29: 0 | F29: 0 | G29: =IF(AND(B29>0,E29>0),(E29-B29)/B29,0) -> 0 | H29: =IF(E29>0,E29-B29,0) -> 0
A30: =Presupuesto!A25 | B30: =D10 -> 0 | C30: 0.3 | D30: =B30*(1+C30) -> 0 | E30: 0 | F30: 0 | G30: =IF(AND(B30>0,E30>0),(E30-B30)/B30,0) -> 0 | H30: =IF(E30>0,E30-B30,0) -> 0
A31: =Presupuesto!A26 | B31: =D11 -> 0 | C31: 0.3 | D31: =B31*(1+C31) -> 0 | E31: 0 | F31: 0 | G31: =IF(AND(B31>0,E31>0),(E31-B31)/B31,0) -> 0 | H31: =IF(E31>0,E31-B31,0) -> 0
A32: =Presupuesto!A27 | B32: =D12 -> 0 | C32: 0.3 | D32: =B32*(1+C32) -> 0 | E32: 0 | F32: 0 | G32: =IF(AND(B32>0,E32>0),(E32-B32)/B32,0) -> 0 | H32: =IF(E32>0,E32-B32,0) -> 0
A33: =Presupuesto!A28 | B33: =D13 -> 0 | C33: 0.3 | D33: =B33*(1+C33) -> 0 | E33: 0 | F33: 0 | G33: =IF(AND(B33>0,E33>0),(E33-B33)/B33,0) -> 0 | H33: =IF(E33>0,E33-B33,0) -> 0
A34: =Presupuesto!A29 | B34: =D14 -> 0 | C34: 0.3 | D34: =B34*(1+C34) -> 0 | E34: 0 | F34: 0 | G34: =IF(AND(B34>0,E34>0),(E34-B34)/B34,0) -> 0 | H34: =IF(E34>0,E34-B34,0) -> 0
... A37: =Presupuesto!A32 | B37: =D17 -> 0 | C37: 0.3 | D37: =B37*(1+C37) -> 0 | E37: 0 | F37: 0 | G37: =IF(AND(B37>0,E37>0),(E37-B37)/B37,0) -> 0 | H37: =IF(E37>0,E37-B37,0) -> 0
A39: SIMULACIÓN DE VENTA (ARS)
A40: TC Venta ARS: | B40: 0
A41: Producto | B41: Costo c/IVA | C41: Margen % | D41: PV Sugerido | E41: PV Final | F41: PV Mercado | G41: Margen Real % | H41: Ganancia Unit
A42: =Presupuesto!A18 | B42: =F3 -> 0 | C42: =C23 -> 0.3 | D42: =B42*(1+C42) -> 0 | E42: =IF(B$40>0,E23*B$40,0) -> 0 | F42: =IF(B$40>0,F23*B$40,0) -> 0 | G42: =IF(AND(B42>0,E42>0),(E42-B42)/B42,0) -> 0 | H42: =IF(E42>0,E42-B42,0) -> 0
A43: =Presupuesto!A19 | B43: =F4 -> 0 | C43: =C24 -> 0.3 | D43: =B43*(1+C43) -> 0 | E43: =IF(B$40>0,E24*B$40,0) -> 0 | F43: =IF(B$40>0,F24*B$40,0) -> 0 | G43: =IF(AND(B43>0,E43>0),(E43-B43)/B43,0) -> 0 | H43: =IF(E43>0,E43-B43,0) -> 0
A44: =Presupuesto!A20 | B44: =F5 -> 0 | C44: =C25 -> 0.3 | D44: =B44*(1+C44) -> 0 | E44: =IF(B$40>0,E25*B$40,0) -> 0 | F44: =IF(B$40>0,F25*B$40,0) -> 0 | G44: =IF(AND(B44>0,E44>0),(E44-B44)/B44,0) -> 0 | H44: =IF(E44>0,E44-B44,0) -> 0
...
